{
  "comments": [
    {
      "unresolved": true,
      "key": {
        "uuid": "473264fe_3c17980d",
        "filename": "ops/posix_mq.rs/src/error.rs",
        "patchSetId": 1
      },
      "lineNbr": 107,
      "author": {
        "id": 1000034
      },
      "writtenOn": "2022-02-04T12:39:17Z",
      "side": 1,
      "message": "Doesn\u0027t UnknownForeignError no longer have any fields?",
      "range": {
        "startLine": 107,
        "startChar": 44,
        "endLine": 107,
        "endChar": 47
      },
      "revId": "505a411fb1c1116a395e7b845e0bade9aceb08a4",
      "serverId": "4fdfa107-4df9-4596-8e0a-1d2bbdd96e36"
    }
  ]
}